<mujoco model="cart-pole">
	<include file="scene.xml"/>
	<compiler inertiafromgeom="true"/>
	<default>
		<joint armature="0" damping="1" limited="true"/>
		<geom contype="0" friction="1 0.1 0.1" material="geom"/>
		<tendon/>
		<motor ctrlrange="-3 3"/>
	</default>
	<statistic center="0.2 0.1 0.45"/>
		
	<visual>
		<global elevation = "-25" azimuth= "115" fovy="45" offwidth = "1500" offheight = "1000"/>
	</visual>
	<option gravity="0 0 -9.81" integrator="RK4" timestep="0.02"/>
	<size nstack="3000"/>
	<worldbody>
		<geom condim="3" material="groundplane" name="floor" pos="0 0 -0.1" size="1.3 1.3 0.1" type="plane"/>
	    <!--  ================= CART POLE ================= /-->
		<geom name="rail" pos="0 0.1 0.6" quat="0.707 0 0.707 0" material="fixed-geom-mat" size="0.02 1.1" type="cylinder"/>
		<geom name="rail-arm-right" pos="1.1 0.2 0.26" quat="0 0 1 0" material="fixed-geom-mat" size="0.03 0.34" type="capsule"/>
		<geom name="rail-connector-right" pos="1.1 0.14 0.6" quat="1 1 0 0" material="fixed-geom-mat" size="0.03 0.06" type="cylinder"/>
		<geom name="rail-base-right" pos="1.1 0.2 -0.09" quat="1 0 0 0" material="fixed-geom-mat" size="0.1 0.01" type="cylinder"/>

		<geom name="rail-arm-left" pos="-1.1 0.2 0.26" quat="0 0 1 0" material="fixed-geom-mat" size="0.03 0.34" type="capsule"/>
		<geom name="rail-connector-left" pos="-1.1 0.14 0.6" quat="1 1 0 0" material="fixed-geom-mat" size="0.03 0.06" type="cylinder"/>
		<geom name="rail-base-left" pos="-1.1 0.2 -0.09" quat="1 0 0 0" material="fixed-geom-mat" size="0.1 0.01" type="cylinder"/>

		<geom name="rail2" pos="0 -0.1 0.6" quat="0.707 0 0.707 0" material="fixed-geom-mat" size="0.02 1.1" type="cylinder"/>
		<geom name="rail2-arm-right" pos="1.1 -0.2 0.26" quat="0 0 1 0" material="fixed-geom-mat" size="0.03 0.34" type="capsule"/>
		<geom name="rail2-connector-right" pos="1.1 -0.14 0.6" quat="1 1 0 0" material="fixed-geom-mat" size="0.03 0.06" type="cylinder"/>
		<geom name="rail2-base-right" pos="1.1 -0.2 -0.09" quat="1 0 0 0" material="fixed-geom-mat" size="0.1 0.01" type="cylinder"/>

		<geom name="rail2-arm-left" pos="-1.1 -0.2 0.26" quat="0 0 1 0" material="fixed-geom-mat" size="0.03 0.34" type="capsule"/>
		<geom name="rail2-connector-left" pos="-1.1 -0.14 0.6" quat="1 1 0 0" material="fixed-geom-mat" size="0.03 0.06" type="cylinder"/>
		<geom name="rail2-base-left" pos="-1.1 -0.2 -0.09" quat="1 0 0 0" material="fixed-geom-mat" size="0.1 0.01" type="cylinder"/>
		
		<body name="cart" pos="0 0 0.6">
			<joint axis="1 0 0" limited="true" name="slider" pos="0 0 0" range="-1 1" type="slide"/>
			<geom name="cart-left" pos="0 0.1 0" quat="0.707 0 0.707 0" size="0.05 0.1" type="cylinder"/>
			<geom name="cart-mid" pos="0 0 0" quat="0 0 1 1" size="0.045 0.1" type="cylinder" material="geom"/>
			<geom name="cart-right" pos="0 -0.1 0" quat="0.707 0 0.707 0" size="0.05 0.1" type="cylinder"/>
			<body name="pole" pos="0 0 0">
				<joint axis="0 1 0" name="hinge" pos="0 0 0" limited="false" range="-80 80" type="hinge" ref="180"/>
				<geom fromto="0 0 0 0.001 0 0.6" name="cpole" size="0.029 0.3 0.029" type="box"/>
				<body name="tip" pos="0.0 0 0.6" quat="1 0 0 0">
					<geom name="tip" size="0.075 0.05" type="cylinder"/>
				</body>
			</body>
		</body>
	</worldbody>
	<actuator>
		<motor ctrllimited="true" ctrlrange="-3 3" gear="100" joint="slider" name="slide"/>
	</actuator>
</mujoco>