<mujoco model="swimmer">
  <include file="scene.xml"/>
  <compiler angle="degree" coordinate="local" inertiafromgeom="true"/>
  <option gravity="0 0 -9.81" density="4000" integrator="RK4" timestep="0.01" viscosity="0.1"/>
  <default>
    <geom conaffinity="0" condim="1" contype="0" material="geom"/>
    <joint armature="0.1"/>
  </default>
  <worldbody>
    <geom condim="3" material="groundplane" name="floor" pos="0 0 -0.1" size="2 2 0.1" type="plane"/>
    <!--  ================= SWIMMER ================= /-->
    <body name="torso" pos="0 0 0">
      <camera name="track" mode="trackcom" pos="0 -3 3" xyaxes="1 0 0 0 1 1"/>
      <geom density="1000" fromto="1.5 0 0 0.5 0 0" size="0.1" type="capsule"/>
      <joint axis="1 0 0" name="slider1" pos="0 0 0" type="slide"/>
      <joint axis="0 1 0" name="slider2" pos="0 0 0" type="slide"/>
      <joint axis="0 0 1" name="free_body_rot" pos="0 0 0" type="hinge"/>
      <body name="mid" pos="0.5 0 0">
        <geom density="1000" fromto="0 0 0 -1 0 0" size="0.1" type="capsule"/>
        <joint axis="0 0 1" limited="true" name="motor1_rot" pos="0 0 0" range="-100 100" type="hinge"/>
        <body name="back" pos="-1 0 0">
          <geom density="1000" fromto="0 0 0 -1 0 0" size="0.1" type="capsule"/>
          <joint axis="0 0 1" limited="true" name="motor2_rot" pos="0 0 0" range="-100 100" type="hinge"/>
        </body>
      </body>
    </body>
  </worldbody>
  <actuator>
    <motor ctrllimited="true" ctrlrange="-1 1" gear="150.0" joint="motor1_rot"/>
    <motor ctrllimited="true" ctrlrange="-1 1" gear="150.0" joint="motor2_rot"/>
  </actuator>
</mujoco>